
Internal Server Error: /myreservation/12191198/
Traceback (most recent call last):
  File "/Users/jinuk/Desktop/geostudyroom/venv/lib/python3.11/site-packages/django/core/handlers/exception.py", line 55, in inner
    response = get_response(request)
               ^^^^^^^^^^^^^^^^^^^^^
  File "/Users/jinuk/Desktop/geostudyroom/venv/lib/python3.11/site-packages/django/core/handlers/base.py", line 197, in _get_response
    response = wrapped_callback(request, *callback_args, **callback_kwargs)
               ^^^^^^^^^^^^^^^^^^^^^^^^^^^^^^^^^^^^^^^^^^^^^^^^^^^^^^^^^^^^
  File "/Users/jinuk/Desktop/geostudyroom/venv/lib/python3.11/site-packages/django/views/decorators/csrf.py", line 56, in wrapper_view
    return view_func(*args, **kwargs)
           ^^^^^^^^^^^^^^^^^^^^^^^^^^
  File "/Users/jinuk/Desktop/geostudyroom/venv/lib/python3.11/site-packages/django/views/generic/base.py", line 104, in view
    return self.dispatch(request, *args, **kwargs)
           ^^^^^^^^^^^^^^^^^^^^^^^^^^^^^^^^^^^^^^^
  File "/Users/jinuk/Desktop/geostudyroom/venv/lib/python3.11/site-packages/rest_framework/views.py", line 509, in dispatch
    response = self.handle_exception(exc)
               ^^^^^^^^^^^^^^^^^^^^^^^^^^
  File "/Users/jinuk/Desktop/geostudyroom/venv/lib/python3.11/site-packages/rest_framework/views.py", line 469, in handle_exception
    self.raise_uncaught_exception(exc)
  File "/Users/jinuk/Desktop/geostudyroom/venv/lib/python3.11/site-packages/rest_framework/views.py", line 480, in raise_uncaught_exception
    raise exc
  File "/Users/jinuk/Desktop/geostudyroom/venv/lib/python3.11/site-packages/rest_framework/views.py", line 506, in dispatch
    response = handler(request, *args, **kwargs)
               ^^^^^^^^^^^^^^^^^^^^^^^^^^^^^^^^^
  File "/Users/jinuk/Desktop/geostudyroom/venv/lib/python3.11/site-packages/django/views/decorators/csrf.py", line 56, in wrapper_view
    return view_func(*args, **kwargs)
           ^^^^^^^^^^^^^^^^^^^^^^^^^^
  File "/Users/jinuk/Desktop/geostudyroom/reserve/views.py", line 419, in get
    reservations=Reservation.objects.filter(user=user).order_by('-month-date')
                 ^^^^^^^^^^^^^^^^^^^^^^^^^^^^^^^^^^^^^^^^^^^^^^^^^^^^^^^^^^^^^
  File "/Users/jinuk/Desktop/geostudyroom/venv/lib/python3.11/site-packages/django/db/models/query.py", line 1659, in order_by
    obj.query.add_ordering(*field_names)
  File "/Users/jinuk/Desktop/geostudyroom/venv/lib/python3.11/site-packages/django/db/models/sql/query.py", line 2221, in add_ordering
    self.names_to_path(item.split(LOOKUP_SEP), self.model._meta)
  File "/Users/jinuk/Desktop/geostudyroom/venv/lib/python3.11/site-packages/django/db/models/sql/query.py", line 1724, in names_to_path
    raise FieldError(
django.core.exceptions.FieldError: Cannot resolve keyword 'month-date' into field. Choices are: clocks, date, id, room, room_id, user, user_id
"GET /myreservation/12191198/ HTTP/1.1" 500 110718
Internal Server Error: /myreservation/12191198/
Traceback (most recent call last):
  File "/Users/jinuk/Desktop/geostudyroom/venv/lib/python3.11/site-packages/django/core/handlers/exception.py", line 55, in inner
    response = get_response(request)
               ^^^^^^^^^^^^^^^^^^^^^
  File "/Users/jinuk/Desktop/geostudyroom/venv/lib/python3.11/site-packages/django/core/handlers/base.py", line 197, in _get_response
    response = wrapped_callback(request, *callback_args, **callback_kwargs)
               ^^^^^^^^^^^^^^^^^^^^^^^^^^^^^^^^^^^^^^^^^^^^^^^^^^^^^^^^^^^^
  File "/Users/jinuk/Desktop/geostudyroom/venv/lib/python3.11/site-packages/django/views/decorators/csrf.py", line 56, in wrapper_view
    return view_func(*args, **kwargs)
           ^^^^^^^^^^^^^^^^^^^^^^^^^^
  File "/Users/jinuk/Desktop/geostudyroom/venv/lib/python3.11/site-packages/django/views/generic/base.py", line 104, in view
    return self.dispatch(request, *args, **kwargs)
           ^^^^^^^^^^^^^^^^^^^^^^^^^^^^^^^^^^^^^^^
  File "/Users/jinuk/Desktop/geostudyroom/venv/lib/python3.11/site-packages/rest_framework/views.py", line 509, in dispatch
    response = self.handle_exception(exc)
               ^^^^^^^^^^^^^^^^^^^^^^^^^^
  File "/Users/jinuk/Desktop/geostudyroom/venv/lib/python3.11/site-packages/rest_framework/views.py", line 469, in handle_exception
    self.raise_uncaught_exception(exc)
  File "/Users/jinuk/Desktop/geostudyroom/venv/lib/python3.11/site-packages/rest_framework/views.py", line 480, in raise_uncaught_exception
    raise exc
  File "/Users/jinuk/Desktop/geostudyroom/venv/lib/python3.11/site-packages/rest_framework/views.py", line 506, in dispatch
    response = handler(request, *args, **kwargs)
               ^^^^^^^^^^^^^^^^^^^^^^^^^^^^^^^^^
  File "/Users/jinuk/Desktop/geostudyroom/venv/lib/python3.11/site-packages/django/views/decorators/csrf.py", line 56, in wrapper_view
    return view_func(*args, **kwargs)
           ^^^^^^^^^^^^^^^^^^^^^^^^^^
  File "/Users/jinuk/Desktop/geostudyroom/reserve/views.py", line 419, in get
    reservations=Reservation.objects.filter(user=user).order_by('-month')
                 ^^^^^^^^^^^^^^^^^^^^^^^^^^^^^^^^^^^^^^^^^^^^^^^^^^^^^^^^
  File "/Users/jinuk/Desktop/geostudyroom/venv/lib/python3.11/site-packages/django/db/models/query.py", line 1659, in order_by
    obj.query.add_ordering(*field_names)
  File "/Users/jinuk/Desktop/geostudyroom/venv/lib/python3.11/site-packages/django/db/models/sql/query.py", line 2221, in add_ordering
    self.names_to_path(item.split(LOOKUP_SEP), self.model._meta)
  File "/Users/jinuk/Desktop/geostudyroom/venv/lib/python3.11/site-packages/django/db/models/sql/query.py", line 1724, in names_to_path
    raise FieldError(
django.core.exceptions.FieldError: Cannot resolve keyword 'month' into field. Choices are: clocks, date, id, room, room_id, user, user_id
"GET /myreservation/12191198/ HTTP/1.1" 500 110638
